changed localhost to localhost1 = no error but site not found now in browser

changed db name in mysqlconnection.py = now does not link to dabase and throws error:
Traceback (most recent call last):
  File "server.py", line 6, in <module>
    mysql = MySQLConnector(app, 'users')
  File "/Users/macuser/Documents/Coding_Dojo_Files/Python_Stack_Files/flask_fundamentals/flask_mysql/mysqlconnection.py", line 46, in MySQLConnector
    return MySQLConnection(app, db)
  File "/Users/macuser/Documents/Coding_Dojo_Files/Python_Stack_Files/flask_fundamentals/flask_mysql/mysqlconnection.py", line 11, in __init__
    'database': db1,  # we got db as an argument
NameError: global name 'db1' is not defined

changed username in MySQLConnection.py to not match MySql database = access denied:
Traceback (most recent call last):
  File "server.py", line 8, in <module>
    print mysql.query_db("SELECT * FROM users")
  File "/Users/macuser/Documents/Coding_Dojo_Files/Python_Stack_Files/flask_fundamentals/flask_mysql/mysqlconnection.py", line 26, in query_db
    result = self.db.session.execute(text(query), data)
  File "/Users/macuser/Documents/Coding_Dojo_Files/Python_Stack_Files/myEnvironments/flaskenv/lib/python2.7/site-packages/sqlalchemy/orm/scoping.py", line 157, in do
    return getattr(self.registry(), name)(*args, **kwargs)
  File "/Users/macuser/Documents/Coding_Dojo_Files/Python_Stack_Files/myEnvironments/flaskenv/lib/python2.7/site-packages/sqlalchemy/orm/session.py", line 1139, in execute
    bind, close_with_result=True).execute(clause, params or {})
  File "/Users/macuser/Documents/Coding_Dojo_Files/Python_Stack_Files/myEnvironments/flaskenv/lib/python2.7/site-packages/sqlalchemy/orm/session.py", line 1003, in _connection_for_bind
    engine, execution_options)
  File "/Users/macuser/Documents/Coding_Dojo_Files/Python_Stack_Files/myEnvironments/flaskenv/lib/python2.7/site-packages/sqlalchemy/orm/session.py", line 403, in _connection_for_bind
    conn = bind.contextual_connect()
  File "/Users/macuser/Documents/Coding_Dojo_Files/Python_Stack_Files/myEnvironments/flaskenv/lib/python2.7/site-packages/sqlalchemy/engine/base.py", line 2112, in contextual_connect
    self._wrap_pool_connect(self.pool.connect, None),
  File "/Users/macuser/Documents/Coding_Dojo_Files/Python_Stack_Files/myEnvironments/flaskenv/lib/python2.7/site-packages/sqlalchemy/engine/base.py", line 2151, in _wrap_pool_connect
    e, dialect, self)
  File "/Users/macuser/Documents/Coding_Dojo_Files/Python_Stack_Files/myEnvironments/flaskenv/lib/python2.7/site-packages/sqlalchemy/engine/base.py", line 1465, in _handle_dbapi_exception_noconnection
    exc_info
  File "/Users/macuser/Documents/Coding_Dojo_Files/Python_Stack_Files/myEnvironments/flaskenv/lib/python2.7/site-packages/sqlalchemy/util/compat.py", line 203, in raise_from_cause
    reraise(type(exception), exception, tb=exc_tb, cause=cause)
  File "/Users/macuser/Documents/Coding_Dojo_Files/Python_Stack_Files/myEnvironments/flaskenv/lib/python2.7/site-packages/sqlalchemy/engine/base.py", line 2147, in _wrap_pool_connect
    return fn()
  File "/Users/macuser/Documents/Coding_Dojo_Files/Python_Stack_Files/myEnvironments/flaskenv/lib/python2.7/site-packages/sqlalchemy/pool.py", line 387, in connect
    return _ConnectionFairy._checkout(self)
  File "/Users/macuser/Documents/Coding_Dojo_Files/Python_Stack_Files/myEnvironments/flaskenv/lib/python2.7/site-packages/sqlalchemy/pool.py", line 766, in _checkout
    fairy = _ConnectionRecord.checkout(pool)
  File "/Users/macuser/Documents/Coding_Dojo_Files/Python_Stack_Files/myEnvironments/flaskenv/lib/python2.7/site-packages/sqlalchemy/pool.py", line 516, in checkout
    rec = pool._do_get()
  File "/Users/macuser/Documents/Coding_Dojo_Files/Python_Stack_Files/myEnvironments/flaskenv/lib/python2.7/site-packages/sqlalchemy/pool.py", line 1138, in _do_get
    self._dec_overflow()
  File "/Users/macuser/Documents/Coding_Dojo_Files/Python_Stack_Files/myEnvironments/flaskenv/lib/python2.7/site-packages/sqlalchemy/util/langhelpers.py", line 66, in __exit__
    compat.reraise(exc_type, exc_value, exc_tb)
  File "/Users/macuser/Documents/Coding_Dojo_Files/Python_Stack_Files/myEnvironments/flaskenv/lib/python2.7/site-packages/sqlalchemy/pool.py", line 1135, in _do_get
    return self._create_connection()
  File "/Users/macuser/Documents/Coding_Dojo_Files/Python_Stack_Files/myEnvironments/flaskenv/lib/python2.7/site-packages/sqlalchemy/pool.py", line 333, in _create_connection
    return _ConnectionRecord(self)
  File "/Users/macuser/Documents/Coding_Dojo_Files/Python_Stack_Files/myEnvironments/flaskenv/lib/python2.7/site-packages/sqlalchemy/pool.py", line 461, in __init__
    self.__connect(first_connect_check=True)
  File "/Users/macuser/Documents/Coding_Dojo_Files/Python_Stack_Files/myEnvironments/flaskenv/lib/python2.7/site-packages/sqlalchemy/pool.py", line 651, in __connect
    connection = pool._invoke_creator(self)
  File "/Users/macuser/Documents/Coding_Dojo_Files/Python_Stack_Files/myEnvironments/flaskenv/lib/python2.7/site-packages/sqlalchemy/engine/strategies.py", line 105, in connect
    return dialect.connect(*cargs, **cparams)
  File "/Users/macuser/Documents/Coding_Dojo_Files/Python_Stack_Files/myEnvironments/flaskenv/lib/python2.7/site-packages/sqlalchemy/engine/default.py", line 393, in connect
    return self.dbapi.connect(*cargs, **cparams)
  File "/Users/macuser/Documents/Coding_Dojo_Files/Python_Stack_Files/myEnvironments/flaskenv/lib/python2.7/site-packages/MySQLdb/__init__.py", line 81, in Connect
    return Connection(*args, **kwargs)
  File "/Users/macuser/Documents/Coding_Dojo_Files/Python_Stack_Files/myEnvironments/flaskenv/lib/python2.7/site-packages/MySQLdb/connections.py", line 193, in __init__
    super(Connection, self).__init__(*args, **kwargs2)
sqlalchemy.exc.OperationalError: (_mysql_exceptions.OperationalError) (1045, "Access denied for user 'root1'@'localhost' (using password: YES)")


changed password on MySQLConnection.py to not match MySql database = access denied:
Traceback (most recent call last):
  File "server.py", line 8, in <module>
    print mysql.query_db("SELECT * FROM users")
  File "/Users/macuser/Documents/Coding_Dojo_Files/Python_Stack_Files/flask_fundamentals/flask_mysql/mysqlconnection.py", line 26, in query_db
    result = self.db.session.execute(text(query), data)
  File "/Users/macuser/Documents/Coding_Dojo_Files/Python_Stack_Files/myEnvironments/flaskenv/lib/python2.7/site-packages/sqlalchemy/orm/scoping.py", line 157, in do
    return getattr(self.registry(), name)(*args, **kwargs)
  File "/Users/macuser/Documents/Coding_Dojo_Files/Python_Stack_Files/myEnvironments/flaskenv/lib/python2.7/site-packages/sqlalchemy/orm/session.py", line 1139, in execute
    bind, close_with_result=True).execute(clause, params or {})
  File "/Users/macuser/Documents/Coding_Dojo_Files/Python_Stack_Files/myEnvironments/flaskenv/lib/python2.7/site-packages/sqlalchemy/orm/session.py", line 1003, in _connection_for_bind
    engine, execution_options)
  File "/Users/macuser/Documents/Coding_Dojo_Files/Python_Stack_Files/myEnvironments/flaskenv/lib/python2.7/site-packages/sqlalchemy/orm/session.py", line 403, in _connection_for_bind
    conn = bind.contextual_connect()
  File "/Users/macuser/Documents/Coding_Dojo_Files/Python_Stack_Files/myEnvironments/flaskenv/lib/python2.7/site-packages/sqlalchemy/engine/base.py", line 2112, in contextual_connect
    self._wrap_pool_connect(self.pool.connect, None),
  File "/Users/macuser/Documents/Coding_Dojo_Files/Python_Stack_Files/myEnvironments/flaskenv/lib/python2.7/site-packages/sqlalchemy/engine/base.py", line 2151, in _wrap_pool_connect
    e, dialect, self)
  File "/Users/macuser/Documents/Coding_Dojo_Files/Python_Stack_Files/myEnvironments/flaskenv/lib/python2.7/site-packages/sqlalchemy/engine/base.py", line 1465, in _handle_dbapi_exception_noconnection
    exc_info
  File "/Users/macuser/Documents/Coding_Dojo_Files/Python_Stack_Files/myEnvironments/flaskenv/lib/python2.7/site-packages/sqlalchemy/util/compat.py", line 203, in raise_from_cause
    reraise(type(exception), exception, tb=exc_tb, cause=cause)
  File "/Users/macuser/Documents/Coding_Dojo_Files/Python_Stack_Files/myEnvironments/flaskenv/lib/python2.7/site-packages/sqlalchemy/engine/base.py", line 2147, in _wrap_pool_connect
    return fn()
  File "/Users/macuser/Documents/Coding_Dojo_Files/Python_Stack_Files/myEnvironments/flaskenv/lib/python2.7/site-packages/sqlalchemy/pool.py", line 387, in connect
    return _ConnectionFairy._checkout(self)
  File "/Users/macuser/Documents/Coding_Dojo_Files/Python_Stack_Files/myEnvironments/flaskenv/lib/python2.7/site-packages/sqlalchemy/pool.py", line 766, in _checkout
    fairy = _ConnectionRecord.checkout(pool)
  File "/Users/macuser/Documents/Coding_Dojo_Files/Python_Stack_Files/myEnvironments/flaskenv/lib/python2.7/site-packages/sqlalchemy/pool.py", line 516, in checkout
    rec = pool._do_get()
  File "/Users/macuser/Documents/Coding_Dojo_Files/Python_Stack_Files/myEnvironments/flaskenv/lib/python2.7/site-packages/sqlalchemy/pool.py", line 1138, in _do_get
    self._dec_overflow()
  File "/Users/macuser/Documents/Coding_Dojo_Files/Python_Stack_Files/myEnvironments/flaskenv/lib/python2.7/site-packages/sqlalchemy/util/langhelpers.py", line 66, in __exit__
    compat.reraise(exc_type, exc_value, exc_tb)
  File "/Users/macuser/Documents/Coding_Dojo_Files/Python_Stack_Files/myEnvironments/flaskenv/lib/python2.7/site-packages/sqlalchemy/pool.py", line 1135, in _do_get
    return self._create_connection()
  File "/Users/macuser/Documents/Coding_Dojo_Files/Python_Stack_Files/myEnvironments/flaskenv/lib/python2.7/site-packages/sqlalchemy/pool.py", line 333, in _create_connection
    return _ConnectionRecord(self)
  File "/Users/macuser/Documents/Coding_Dojo_Files/Python_Stack_Files/myEnvironments/flaskenv/lib/python2.7/site-packages/sqlalchemy/pool.py", line 461, in __init__
    self.__connect(first_connect_check=True)
  File "/Users/macuser/Documents/Coding_Dojo_Files/Python_Stack_Files/myEnvironments/flaskenv/lib/python2.7/site-packages/sqlalchemy/pool.py", line 651, in __connect
    connection = pool._invoke_creator(self)
  File "/Users/macuser/Documents/Coding_Dojo_Files/Python_Stack_Files/myEnvironments/flaskenv/lib/python2.7/site-packages/sqlalchemy/engine/strategies.py", line 105, in connect
    return dialect.connect(*cargs, **cparams)
  File "/Users/macuser/Documents/Coding_Dojo_Files/Python_Stack_Files/myEnvironments/flaskenv/lib/python2.7/site-packages/sqlalchemy/engine/default.py", line 393, in connect
    return self.dbapi.connect(*cargs, **cparams)
  File "/Users/macuser/Documents/Coding_Dojo_Files/Python_Stack_Files/myEnvironments/flaskenv/lib/python2.7/site-packages/MySQLdb/__init__.py", line 81, in Connect
    return Connection(*args, **kwargs)
  File "/Users/macuser/Documents/Coding_Dojo_Files/Python_Stack_Files/myEnvironments/flaskenv/lib/python2.7/site-packages/MySQLdb/connections.py", line 193, in __init__
    super(Connection, self).__init__(*args, **kwargs2)
sqlalchemy.exc.OperationalError: (_mysql_exceptions.OperationalError) (1045, "Access denied for user 'root1'@'localhost' (using password: YES)")
(flaskenv) ➜  flask_mysql
(flaskenv) ➜  flask_mysql python server.py
Traceback (most recent call last):
  File "server.py", line 8, in <module>
    print mysql.query_db("SELECT * FROM users")
  File "/Users/macuser/Documents/Coding_Dojo_Files/Python_Stack_Files/flask_fundamentals/flask_mysql/mysqlconnection.py", line 26, in query_db
    result = self.db.session.execute(text(query), data)
  File "/Users/macuser/Documents/Coding_Dojo_Files/Python_Stack_Files/myEnvironments/flaskenv/lib/python2.7/site-packages/sqlalchemy/orm/scoping.py", line 157, in do
    return getattr(self.registry(), name)(*args, **kwargs)
  File "/Users/macuser/Documents/Coding_Dojo_Files/Python_Stack_Files/myEnvironments/flaskenv/lib/python2.7/site-packages/sqlalchemy/orm/session.py", line 1139, in execute
    bind, close_with_result=True).execute(clause, params or {})
  File "/Users/macuser/Documents/Coding_Dojo_Files/Python_Stack_Files/myEnvironments/flaskenv/lib/python2.7/site-packages/sqlalchemy/orm/session.py", line 1003, in _connection_for_bind
    engine, execution_options)
  File "/Users/macuser/Documents/Coding_Dojo_Files/Python_Stack_Files/myEnvironments/flaskenv/lib/python2.7/site-packages/sqlalchemy/orm/session.py", line 403, in _connection_for_bind
    conn = bind.contextual_connect()
  File "/Users/macuser/Documents/Coding_Dojo_Files/Python_Stack_Files/myEnvironments/flaskenv/lib/python2.7/site-packages/sqlalchemy/engine/base.py", line 2112, in contextual_connect
    self._wrap_pool_connect(self.pool.connect, None),
  File "/Users/macuser/Documents/Coding_Dojo_Files/Python_Stack_Files/myEnvironments/flaskenv/lib/python2.7/site-packages/sqlalchemy/engine/base.py", line 2151, in _wrap_pool_connect
    e, dialect, self)
  File "/Users/macuser/Documents/Coding_Dojo_Files/Python_Stack_Files/myEnvironments/flaskenv/lib/python2.7/site-packages/sqlalchemy/engine/base.py", line 1465, in _handle_dbapi_exception_noconnection
    exc_info
  File "/Users/macuser/Documents/Coding_Dojo_Files/Python_Stack_Files/myEnvironments/flaskenv/lib/python2.7/site-packages/sqlalchemy/util/compat.py", line 203, in raise_from_cause
    reraise(type(exception), exception, tb=exc_tb, cause=cause)
  File "/Users/macuser/Documents/Coding_Dojo_Files/Python_Stack_Files/myEnvironments/flaskenv/lib/python2.7/site-packages/sqlalchemy/engine/base.py", line 2147, in _wrap_pool_connect
    return fn()
  File "/Users/macuser/Documents/Coding_Dojo_Files/Python_Stack_Files/myEnvironments/flaskenv/lib/python2.7/site-packages/sqlalchemy/pool.py", line 387, in connect
    return _ConnectionFairy._checkout(self)
  File "/Users/macuser/Documents/Coding_Dojo_Files/Python_Stack_Files/myEnvironments/flaskenv/lib/python2.7/site-packages/sqlalchemy/pool.py", line 766, in _checkout
    fairy = _ConnectionRecord.checkout(pool)
  File "/Users/macuser/Documents/Coding_Dojo_Files/Python_Stack_Files/myEnvironments/flaskenv/lib/python2.7/site-packages/sqlalchemy/pool.py", line 516, in checkout
    rec = pool._do_get()
  File "/Users/macuser/Documents/Coding_Dojo_Files/Python_Stack_Files/myEnvironments/flaskenv/lib/python2.7/site-packages/sqlalchemy/pool.py", line 1138, in _do_get
    self._dec_overflow()
  File "/Users/macuser/Documents/Coding_Dojo_Files/Python_Stack_Files/myEnvironments/flaskenv/lib/python2.7/site-packages/sqlalchemy/util/langhelpers.py", line 66, in __exit__
    compat.reraise(exc_type, exc_value, exc_tb)
  File "/Users/macuser/Documents/Coding_Dojo_Files/Python_Stack_Files/myEnvironments/flaskenv/lib/python2.7/site-packages/sqlalchemy/pool.py", line 1135, in _do_get
    return self._create_connection()
  File "/Users/macuser/Documents/Coding_Dojo_Files/Python_Stack_Files/myEnvironments/flaskenv/lib/python2.7/site-packages/sqlalchemy/pool.py", line 333, in _create_connection
    return _ConnectionRecord(self)
  File "/Users/macuser/Documents/Coding_Dojo_Files/Python_Stack_Files/myEnvironments/flaskenv/lib/python2.7/site-packages/sqlalchemy/pool.py", line 461, in __init__
    self.__connect(first_connect_check=True)
  File "/Users/macuser/Documents/Coding_Dojo_Files/Python_Stack_Files/myEnvironments/flaskenv/lib/python2.7/site-packages/sqlalchemy/pool.py", line 651, in __connect
    connection = pool._invoke_creator(self)
  File "/Users/macuser/Documents/Coding_Dojo_Files/Python_Stack_Files/myEnvironments/flaskenv/lib/python2.7/site-packages/sqlalchemy/engine/strategies.py", line 105, in connect
    return dialect.connect(*cargs, **cparams)
  File "/Users/macuser/Documents/Coding_Dojo_Files/Python_Stack_Files/myEnvironments/flaskenv/lib/python2.7/site-packages/sqlalchemy/engine/default.py", line 393, in connect
    return self.dbapi.connect(*cargs, **cparams)
  File "/Users/macuser/Documents/Coding_Dojo_Files/Python_Stack_Files/myEnvironments/flaskenv/lib/python2.7/site-packages/MySQLdb/__init__.py", line 81, in Connect
    return Connection(*args, **kwargs)
  File "/Users/macuser/Documents/Coding_Dojo_Files/Python_Stack_Files/myEnvironments/flaskenv/lib/python2.7/site-packages/MySQLdb/connections.py", line 193, in __init__
    super(Connection, self).__init__(*args, **kwargs2)
sqlalchemy.exc.OperationalError: (_mysql_exceptions.OperationalError) (1045, "Access denied for user 'root'@'localhost' (using password: YES)")


Changed port number in MySQLConnector.py to not match MySql database = never connects to database, no error message,  terminal just hangs and does not return to command line.
